Workbook

Sheet Datos
A1: Sepal Length | B1: Sepal Width | C1: Petal Length | D1: Petal Width | E1: Species | F1: Sepal Length (Cat) | G1: Sepal Width (Cat) | H1: Petal Length (Cat) | I1: Petal Width (Cat) | J1: Species
A2: 5.1 | B2: 3.5 | C2: 1.4 | D2: 0.2 | E2: Iris-setosa | F2: =IF(A2<=Rangos!$C$2,"chico",IF(A2<=Rangos!$D$2,"mediano","grande")) -> chico | G2: =IF(B2<=Rangos!$C$3,"chico",IF(B2<=Rangos!$D$3,"mediano","grande")) -> grande | H2: =IF(C2<=Rangos!$C$4,"chico",IF(C2<=Rangos!$D$4,"mediano","grande")) -> chico | I2: =IF(D2<=Rangos!$C$5,"chico",IF(D2<=Rangos!$D$5,"mediano","grande")) -> chico | J2: Iris-setosa
A3: 4.9 | B3: 3 | C3: 1.4 | D3: 0.2 | E3: Iris-setosa | F3: =IF(A3<=Rangos!$C$2,"chico",IF(A3<=Rangos!$D$2,"mediano","grande")) -> chico | G3: =IF(B3<=Rangos!$C$3,"chico",IF(B3<=Rangos!$D$3,"mediano","grande")) -> mediano | H3: =IF(C3<=Rangos!$C$4,"chico",IF(C3<=Rangos!$D$4,"mediano","grande")) -> chico | I3: =IF(D3<=Rangos!$C$5,"chico",IF(D3<=Rangos!$D$5,"mediano","grande")) -> chico | J3: Iris-setosa
A4: 4.7 | B4: 3.2 | C4: 1.3 | D4: 0.2 | E4: Iris-setosa | F4: =IF(A4<=Rangos!$C$2,"chico",IF(A4<=Rangos!$D$2,"mediano","grande")) -> chico | G4: =IF(B4<=Rangos!$C$3,"chico",IF(B4<=Rangos!$D$3,"mediano","grande")) -> mediano | H4: =IF(C4<=Rangos!$C$4,"chico",IF(C4<=Rangos!$D$4,"mediano","grande")) -> chico | I4: =IF(D4<=Rangos!$C$5,"chico",IF(D4<=Rangos!$D$5,"mediano","grande")) -> chico | J4: Iris-setosa
A5: 4.6 | B5: 3.1 | C5: 1.5 | D5: 0.2 | E5: Iris-setosa | F5: =IF(A5<=Rangos!$C$2,"chico",IF(A5<=Rangos!$D$2,"mediano","grande")) -> chico | G5: =IF(B5<=Rangos!$C$3,"chico",IF(B5<=Rangos!$D$3,"mediano","grande")) -> mediano | H5: =IF(C5<=Rangos!$C$4,"chico",IF(C5<=Rangos!$D$4,"mediano","grande")) -> chico | I5: =IF(D5<=Rangos!$C$5,"chico",IF(D5<=Rangos!$D$5,"mediano","grande")) -> chico | J5: Iris-setosa
A6: 5 | B6: 3.6 | C6: 1.4 | D6: 0.2 | E6: Iris-setosa | F6: =IF(A6<=Rangos!$C$2,"chico",IF(A6<=Rangos!$D$2,"mediano","grande")) -> chico | G6: =IF(B6<=Rangos!$C$3,"chico",IF(B6<=Rangos!$D$3,"mediano","grande")) -> grande | H6: =IF(C6<=Rangos!$C$4,"chico",IF(C6<=Rangos!$D$4,"mediano","grande")) -> chico | I6: =IF(D6<=Rangos!$C$5,"chico",IF(D6<=Rangos!$D$5,"mediano","grande")) -> chico | J6: Iris-setosa
A7: 5.4 | B7: 3.9 | C7: 1.7 | D7: 0.4 | E7: Iris-setosa | F7: =IF(A7<=Rangos!$C$2,"chico",IF(A7<=Rangos!$D$2,"mediano","grande")) -> chico | G7: =IF(B7<=Rangos!$C$3,"chico",IF(B7<=Rangos!$D$3,"mediano","grande")) -> grande | H7: =IF(C7<=Rangos!$C$4,"chico",IF(C7<=Rangos!$D$4,"mediano","grande")) -> chico | I7: =IF(D7<=Rangos!$C$5,"chico",IF(D7<=Rangos!$D$5,"mediano","grande")) -> chico | J7: Iris-setosa
A8: 4.6 | B8: 3.4 | C8: 1.4 | D8: 0.3 | E8: Iris-setosa | F8: =IF(A8<=Rangos!$C$2,"chico",IF(A8<=Rangos!$D$2,"mediano","grande")) -> chico | G8: =IF(B8<=Rangos!$C$3,"chico",IF(B8<=Rangos!$D$3,"mediano","grande")) -> grande | H8: =IF(C8<=Rangos!$C$4,"chico",IF(C8<=Rangos!$D$4,"mediano","grande")) -> chico | I8: =IF(D8<=Rangos!$C$5,"chico",IF(D8<=Rangos!$D$5,"mediano","grande")) -> chico | J8: Iris-setosa
A9: 5 | B9: 3.4 | C9: 1.5 | D9: 0.2 | E9: Iris-setosa | F9: =IF(A9<=Rangos!$C$2,"chico",IF(A9<=Rangos!$D$2,"mediano","grande")) -> chico | G9: =IF(B9<=Rangos!$C$3,"chico",IF(B9<=Rangos!$D$3,"mediano","grande")) -> grande | H9: =IF(C9<=Rangos!$C$4,"chico",IF(C9<=Rangos!$D$4,"mediano","grande")) -> chico | I9: =IF(D9<=Rangos!$C$5,"chico",IF(D9<=Rangos!$D$5,"mediano","grande")) -> chico | J9: Iris-setosa
A10: 4.4 | B10: 2.9 | C10: 1.4 | D10: 0.2 | E10: Iris-setosa | F10: =IF(A10<=Rangos!$C$2,"chico",IF(A10<=Rangos!$D$2,"mediano","grande")) -> chico | G10: =IF(B10<=Rangos!$C$3,"chico",IF(B10<=Rangos!$D$3,"mediano","grande")) -> chico | H10: =IF(C10<=Rangos!$C$4,"chico",IF(C10<=Rangos!$D$4,"mediano","grande")) -> chico | I10: =IF(D10<=Rangos!$C$5,"chico",IF(D10<=Rangos!$D$5,"mediano","grande")) -> chico | J10: Iris-setosa
A11: 4.9 | B11: 3.1 | C11: 1.5 | D11: 0.1 | E11: Iris-setosa | F11: =IF(A11<=Rangos!$C$2,"chico",IF(A11<=Rangos!$D$2,"mediano","grande")) -> chico | G11: =IF(B11<=Rangos!$C$3,"chico",IF(B11<=Rangos!$D$3,"mediano","grande")) -> mediano | H11: =IF(C11<=Rangos!$C$4,"chico",IF(C11<=Rangos!$D$4,"mediano","grande")) -> chico | I11: =IF(D11<=Rangos!$C$5,"chico",IF(D11<=Rangos!$D$5,"mediano","grande")) -> chico | J11: Iris-setosa
A12: 5.4 | B12: 3.7 | C12: 1.5 | D12: 0.2 | E12: Iris-setosa | F12: =IF(A12<=Rangos!$C$2,"chico",IF(A12<=Rangos!$D$2,"mediano","grande")) -> chico | G12: =IF(B12<=Rangos!$C$3,"chico",IF(B12<=Rangos!$D$3,"mediano","grande")) -> grande | H12: =IF(C12<=Rangos!$C$4,"chico",IF(C12<=Rangos!$D$4,"mediano","grande")) -> chico | I12: =IF(D12<=Rangos!$C$5,"chico",IF(D12<=Rangos!$D$5,"mediano","grande")) -> chico | J12: Iris-setosa
A13: 4.8 | B13: 3.4 | C13: 1.6 | D13: 0.2 | E13: Iris-setosa | F13: =IF(A13<=Rangos!$C$2,"chico",IF(A13<=Rangos!$D$2,"mediano","grande")) -> chico | G13: =IF(B13<=Rangos!$C$3,"chico",IF(B13<=Rangos!$D$3,"mediano","grande")) -> grande | H13: =IF(C13<=Rangos!$C$4,"chico",IF(C13<=Rangos!$D$4,"mediano","grande")) -> chico | I13: =IF(D13<=Rangos!$C$5,"chico",IF(D13<=Rangos!$D$5,"mediano","grande")) -> chico | J13: Iris-setosa
... A151: 5.9 | B151: 3 | C151: 5.1 | D151: 1.8 | E151: Iris-virginica | F151: =IF(A151<=Rangos!$C$2,"chico",IF(A151<=Rangos!$D$2,"mediano","grande")) -> mediano | G151: =IF(B151<=Rangos!$C$3,"chico",IF(B151<=Rangos!$D$3,"mediano","grande")) -> mediano | H151: =IF(C151<=Rangos!$C$4,"chico",IF(C151<=Rangos!$D$4,"mediano","grande")) -> grande | I151: =IF(D151<=Rangos!$C$5,"chico",IF(D151<=Rangos!$D$5,"mediano","grande")) -> grande | J151: Iris-virginica

Sheet Rangos
A1: Variable | B1: Valor Min | C1: Corte Chico (33.3%) | D1: Corte Mediano (66.7%) | E1: Valor Max | F1: Rangos definidos
A2: Sepal Length | B2: 4.3 | C2: 5.4 | D2: 6.3 | E2: 7.9 | F2: Chico <= 5.4 | Mediano <= 6.3 | Grande > 6.3
A3: Sepal Width | B3: 2 | C3: 2.9 | D3: 3.2 | E3: 4.4 | F3: Chico <= 2.9 | Mediano <= 3.2 | Grande > 3.2
A4: Petal Length | B4: 1 | C4: 2.4 | D4: 4.9 | E4: 6.9 | F4: Chico <= 2.4 | Mediano <= 4.9 | Grande > 4.9
A5: Petal Width | B5: 0.1 | C5: 0.8 | D5: 1.6 | E5: 2.5 | F5: Chico <= 0.8 | Mediano <= 1.6 | Grande > 1.6

Sheet Calculos_ID3
A1: PASO 1: DESORDEN INICIAL DE TODAS LAS FLORES (ENTROPÍA TOTAL S)
A2: Tipo de Flor | B2: Cantidad de flores | C2: Probabilidad p(i) | D2: Desorden por flor
A3: Iris-setosa | B3: 50 | C3: 0.3333 | D3: 0.5283
A4: Iris-versicolor | B4: 50 | C4: 0.3333 | D4: 0.5283
A5: Iris-virginica | B5: 50 | C5: 0.3333 | D5: 0.5283
A6: Total en la base (S) | B6: 150 | C6: 1 | D6: 1.585
A8: PROBANDO VARIABLES PARA ELEGIR LA RAÍZ DEL ÁRBOL
A9: Prueba con: Petal Width (Ancho del pétalo)
A10: Categoría | B10: Setosa | C10: Versicolor | D10: Virginica | E10: Total grupo | F10: p(Setosa) | G10: p(Versicolor) | H10: p(Virginica) | I10: Entropía grupo | J10: Peso en la base | K10: Entropía ponderada
A11: chico | B11: 50 | C11: 0 | D11: 0 | E11: 50 | F11: 1 | G11: 0 | H11: 0 | I11: 0 | J11: 0.3333 | K11: 0
A12: mediano | B12: 0 | C12: 48 | D12: 4 | E12: 52 | F12: 0 | G12: 0.9231 | H12: 0.0769 | I12: 0.3912 | J12: 0.3467 | K12: 0.1356
A13: grande | B13: 0 | C13: 2 | D13: 46 | E13: 48 | F13: 0 | G13: 0.0417 | H13: 0.9583 | I13: 0.25 | J13: 0.32 | K13: 0.08
A14: Suma total y ganancia | B14: 50 | C14: 50 | D14: 50 | E14: 150 | J14: Ganancia lograda: | K14: 1.3694
A16: Prueba con: Petal Length (Largo del pétalo)
A17: Categoría | B17: Setosa | C17: Versicolor | D17: Virginica | E17: Total grupo | F17: p(Setosa) | G17: p(Versicolor) | H17: p(Virginica) | I17: Entropía grupo | J17: Peso en la base | K17: Entropía ponderada
A18: chico | B18: 50 | C18: 0 | D18: 0 | E18: 50 | F18: 1 | G18: 0 | H18: 0 | I18: 0 | J18: 0.3333 | K18: 0
A19: mediano | B19: 0 | C19: 48 | D19: 6 | E19: 54 | F19: 0 | G19: 0.8889 | H19: 0.1111 | I19: 0.5032 | J19: 0.36 | K19: 0.1812
A20: grande | B20: 0 | C20: 2 | D20: 44 | E20: 46 | F20: 0 | G20: 0.0435 | H20: 0.9565 | I20: 0.2581 | J20: 0.3067 | K20: 0.0792
A21: Suma total y ganancia | B21: 50 | C21: 50 | D21: 50 | E21: 150 | J21: Ganancia lograda: | K21: 1.3246
A23: Prueba con: Sepal Length (Largo del sépalo)
A24: Categoría | B24: Setosa | C24: Versicolor | D24: Virginica | E24: Total grupo | F24: p(Setosa) | G24: p(Versicolor) | H24: p(Virginica) | I24: Entropía grupo | J24: Peso en la base | K24: Entropía ponderada
A25: chico | B25: 45 | C25: 6 | D25: 1 | E25: 52 | F25: 0.8654 | G25: 0.1154 | H25: 0.0192 | I25: 0.6495 | J25: 0.3467 | K25: 0.2252
A26: mediano | B26: 5 | C26: 33 | D26: 18 | E26: 56 | F26: 0.0893 | G26: 0.5893 | H26: 0.3214 | I26: 1.2871 | J26: 0.3733 | K26: 0.4805
A27: grande | B27: 0 | C27: 11 | D27: 31 | E27: 42 | F27: 0 | G27: 0.2619 | H27: 0.7381 | I27: 0.8296 | J27: 0.28 | K27: 0.2323
A28: Suma total y ganancia | B28: 50 | C28: 50 | D28: 50 | E28: 150 | J28: Ganancia lograda: | K28: 0.647
A30: Prueba con: Sepal Width (Ancho del sépalo)
A31: Categoría | B31: Setosa | C31: Versicolor | D31: Virginica | E31: Total grupo | F31: p(Setosa) | G31: p(Versicolor) | H31: p(Virginica) | I31: Entropía grupo | J31: Peso en la base | K31: Entropía ponderada
A32: chico | B32: 2 | C32: 34 | D32: 21 | E32: 57 | F32: 0.0351 | G32: 0.5965 | H32: 0.3684 | I32: 1.145 | J32: 0.38 | K32: 0.4351
A33: mediano | B33: 16 | C33: 14 | D33: 21 | E33: 51 | F33: 0.3137 | G33: 0.2745 | H33: 0.4118 | I33: 1.5638 | J33: 0.34 | K33: 0.5317
A34: grande | B34: 32 | C34: 2 | D34: 8 | E34: 42 | F34: 0.7619 | G34: 0.0476 | H34: 0.1905 | I34: 0.9637 | J34: 0.28 | K34: 0.2698
A35: Suma total y ganancia | B35: 50 | C35: 50 | D35: 50 | E35: 150 | J35: Ganancia lograda: | K35: 0.3484
A37: Tabla comparativa para ver cuál variable gana la raíz
A38: Variable probada | B38: Desorden inicial (S) | C38: Desorden sobrante | D38: Ganancia (Gain) | E38: ¿Quién gana?
A39: Petal Width | B39: 1.585 | C39: 0.2156 | D39: 1.3694 | E39: GANA Y QUEDA COMO RAÍZ
A40: Petal Length | B40: 1.585 | C40: 0.2604 | D40: 1.3246 | E40: Queda fuera
A41: Sepal Length | B41: 1.585 | C41: 0.938 | D41: 0.647 | E41: Queda fuera
A42: Sepal Width | B42: 1.585 | C42: 1.2366 | D42: 0.3484 | E42: Queda fuera
A44: PASO 2: ABRIENDO LA RAMA DE PETAL WIDTH = MEDIANO (52 FLORES)
A45: Tipo de Flor | B45: Flores en este grupo | C45: Probabilidad | D45: Desorden
A46: Iris-setosa | B46: 0 | C46: 0 | D46: 0
...
